Traceback (most recent call last):
  File "/opt/hostedtoolcache/Python/3.8.17/x64/lib/python3.8/site-packages/jupyter_cache/executors/utils.py", line 51, in single_nb_execution
    executenb(
  File "/opt/hostedtoolcache/Python/3.8.17/x64/lib/python3.8/site-packages/nbclient/client.py", line 1204, in execute
    return NotebookClient(nb=nb, resources=resources, km=km, **kwargs).execute()
  File "/opt/hostedtoolcache/Python/3.8.17/x64/lib/python3.8/site-packages/nbclient/util.py", line 84, in wrapped
    return just_run(coro(*args, **kwargs))
  File "/opt/hostedtoolcache/Python/3.8.17/x64/lib/python3.8/site-packages/nbclient/util.py", line 62, in just_run
    return loop.run_until_complete(coro)
  File "/opt/hostedtoolcache/Python/3.8.17/x64/lib/python3.8/asyncio/base_events.py", line 616, in run_until_complete
    return future.result()
  File "/opt/hostedtoolcache/Python/3.8.17/x64/lib/python3.8/site-packages/nbclient/client.py", line 663, in async_execute
    await self.async_execute_cell(
  File "/opt/hostedtoolcache/Python/3.8.17/x64/lib/python3.8/site-packages/nbclient/client.py", line 965, in async_execute_cell
    await self._check_raise_for_error(cell, cell_index, exec_reply)
  File "/opt/hostedtoolcache/Python/3.8.17/x64/lib/python3.8/site-packages/nbclient/client.py", line 862, in _check_raise_for_error
    raise CellExecutionError.from_cell_and_msg(cell, exec_reply_content)
nbclient.exceptions.CellExecutionError: An error occurred while executing the following cell:
------------------
import statistics as stat
import matplotlib.pyplot as plt

x = (0, 2, 2, 3, 4, 5.6)
y = (-1, -3, -4, -5, 4, -7)

slope, intercept = stat.linear_regression(x, y)

start_point, end_point = min(x), max(x)
image_start_point = slope * start_point + intercept
image_end_point = slope * end_point + intercept

plt.figure()
plt.scatter(x, y)
plt.plot((start_point, end_point), (image_start_point, image_end_point))
plt.xlabel("$x$")
plt.ylabel("$y$")
------------------

[0;31m---------------------------------------------------------------------------[0m
[0;31mAttributeError[0m                            Traceback (most recent call last)
Cell [0;32mIn[1], line 7[0m
[1;32m      4[0m x [38;5;241m=[39m ([38;5;241m0[39m, [38;5;241m2[39m, [38;5;241m2[39m, [38;5;241m3[39m, [38;5;241m4[39m, [38;5;241m5.6[39m)
[1;32m      5[0m y [38;5;241m=[39m ([38;5;241m-[39m[38;5;241m1[39m, [38;5;241m-[39m[38;5;241m3[39m, [38;5;241m-[39m[38;5;241m4[39m, [38;5;241m-[39m[38;5;241m5[39m, [38;5;241m4[39m, [38;5;241m-[39m[38;5;241m7[39m)
[0;32m----> 7[0m slope, intercept [38;5;241m=[39m [43mstat[49m[38;5;241;43m.[39;49m[43mlinear_regression[49m(x, y)
[1;32m      9[0m start_point, end_point [38;5;241m=[39m [38;5;28mmin[39m(x), [38;5;28mmax[39m(x)
[1;32m     10[0m image_start_point [38;5;241m=[39m slope [38;5;241m*[39m start_point [38;5;241m+[39m intercept

[0;31mAttributeError[0m: module 'statistics' has no attribute 'linear_regression'
AttributeError: module 'statistics' has no attribute 'linear_regression'

